<?xml version="1.0" ?>
<sdf version="1.6">
    <world name="default">
        <physics name="1ms" type="dart">
            <max_step_size>0.001</max_step_size>
            <real_time_factor>1.0</real_time_factor>
        </physics>
        <plugin filename="libignition-gazebo-physics-system.so" name="ignition::gazebo::systems::Physics">
        </plugin>
        <plugin filename="libignition-gazebo-user-commands-system.so" name="ignition::gazebo::systems::UserCommands">
        </plugin>
        <plugin filename="libignition-gazebo-scene-broadcaster-system.so" name="ignition::gazebo::systems::SceneBroadcaster">
        </plugin>

        <light type="directional" name="sun">
            <cast_shadows>true</cast_shadows>
            <pose>0 0 10 0 0 0</pose>
            <diffuse>0.8 0.8 0.8 1</diffuse>
            <specular>0.2 0.2 0.2 1</specular>
            <attenuation>
                <range>1000</range>
                <constant>0.9</constant>
                <linear>0.01</linear>
                <quadratic>0.001</quadratic>
            </attenuation>
            <direction>-0.5 0.1 -0.9</direction>
        </light>

        <model name="ground_plane">
            <static>true</static>
            <link name="link">
                <collision name="collision">
                    <geometry>
                        <plane>
                            <normal>0 0 1</normal>
                        </plane>
                    </geometry>
                </collision>
                <visual name="visual">
                    <geometry>
                        <plane>
                            <normal>0 0 1</normal>
                            <size>100 100</size>
                        </plane>
                    </geometry>
                    <material>
                        <ambient>0.8 0.8 0.8 1</ambient>
                        <diffuse>0.8 0.8 0.8 1</diffuse>
                        <specular>0.8 0.8 0.8 1</specular>
                    </material>
                </visual>
            </link>
        </model>

        <model name='thirabot'>
            <link name='base_footprint'>
                <pose frame=''>0 0 0 0 -0 0</pose>
                <inertial>
                    <pose frame=''>0 0 0.15 0 -0 0</pose>
                    <mass>100</mass>
                    <inertia>
                        <ixx>2.85417</ixx>
                        <ixy>0</ixy>
                        <ixz>0</ixz>
                        <iyy>8.66667</iyy>
                        <iyz>0</iyz>
                        <izz>10.8542</izz>
                    </inertia>
                </inertial>
                <collision name='base_footprint_fixed_joint_lump__base_link_collision'>
                    <pose frame=''>0 0 0.15 0 -0 0</pose>
                    <geometry>
                        <box>
                            <size>1 0.55 0.2</size>
                        </box>
                    </geometry>
                </collision>
                <visual name='base_footprint_fixed_joint_lump__base_link_visual'>
                    <pose frame=''>0 0 0.15 0 -0 0</pose>
                    <geometry>
                        <box>
                            <size>1 0.55 0.2</size>
                        </box>
                    </geometry>
                    <material>
                        <ambient>0.4 0.4 0.8 1</ambient>
                        <diffuse>0.4 0.4 0.8 1</diffuse>
                        <specular>0.4 0.4 0.8 1</specular>
                    </material>
                </visual>
            </link>

            <link name='l_bogie_suspension'>
                <pose frame=''>-0.25 0.36 0.15 0 -0 0</pose>
                <inertial>
                    <pose frame=''>0 -0.01 0 1.5708 -0 0</pose>
                    <mass>2</mass>
                    <inertia>
                        <ixx>0.00151667</ixx>
                        <ixy>0</ixy>
                        <ixz>0</ixz>
                        <iyy>0.00151667</iyy>
                        <iyz>0</iyz>
                        <izz>0.0009</izz>
                    </inertia>
                </inertial>
                <collision name='l_bogie_suspension_collision'>
                    <pose frame=''>0 -0.01 0 1.5708 -0 0</pose>
                    <geometry>
                        <cylinder>
                            <length>0.08</length>
                            <radius>0.03</radius>
                        </cylinder>
                    </geometry>
                </collision>
                <visual name='l_bogie_suspension_visual'>
                    <pose frame=''>0 -0.01 0 1.5708 -0 0</pose>
                    <geometry>
                        <cylinder>
                            <length>0.08</length>
                            <radius>0.03</radius>
                        </cylinder>
                    </geometry>
                    <material>
                        <ambient>0.6 0.4 0.4 1</ambient>
                        <diffuse>0.6 0.4 0.4 1</diffuse>
                        <specular>0.6 0.4 0.4 1</specular>
                    </material>
                </visual>
            </link>

            <joint name='l_bogie_suspension_joint' type='revolute'>
                <child>l_bogie_suspension</child>
                <parent>base_footprint</parent>
                <axis>
                    <xyz>0 1 0</xyz>
                    <limit>
                        <lower>-3.14159</lower>
                        <upper>3.14159</upper>
                        <effort>1000</effort>
                        <velocity>0.1</velocity>
                    </limit>
                    <dynamics>
                        <spring_reference>0</spring_reference>
                        <spring_stiffness>0</spring_stiffness>
                    </dynamics>
                    <use_parent_model_frame>1</use_parent_model_frame>
                </axis>
            </joint>

            <link name='l_rear_caster_rotate'>
                <pose frame=''>-0.43 0.37 0.15 0 -0 0</pose>
                <inertial>
                    <pose frame=''>0 0 0 0 -0 0</pose>
                    <mass>2</mass>
                    <inertia>
                        <ixx>0.0006</ixx>
                        <ixy>0</ixy>
                        <ixz>0</ixz>
                        <iyy>0.0006</iyy>
                        <iyz>0</iyz>
                        <izz>0.0009</izz>
                    </inertia>
                </inertial>
                <collision name='l_rear_caster_rotate_collision'>
                    <pose frame=''>0 0 0 0 -0 0</pose>
                    <geometry>
                        <cylinder>
                            <length>0.03</length>
                            <radius>0.03</radius>
                        </cylinder>
                    </geometry>
                </collision>
                <visual name='l_rear_caster_rotate_visual'>
                    <pose frame=''>0 0 0 0 -0 0</pose>
                    <geometry>
                        <cylinder>
                            <length>0.03</length>
                            <radius>0.03</radius>
                        </cylinder>
                    </geometry>
                    <material>
                        <ambient>0.3 0.3 0.3 1</ambient>
                        <diffuse>0.3 0.3 0.3 1</diffuse>
                        <specular>0.3 0.3 0.3 1</specular>
                    </material>
                </visual>
            </link>

            <joint name='l_rear_caster_rotate_joint' type='revolute'>
                <child>l_rear_caster_rotate</child>
                <parent>l_bogie_suspension</parent>
                <axis>
                    <xyz>0 0 1</xyz>
                    <limit>
                        <lower>-1e+16</lower>
                        <upper>1e+16</upper>
                    </limit>
                    <dynamics>
                        <spring_reference>0</spring_reference>
                        <spring_stiffness>0</spring_stiffness>
                    </dynamics>
                    <use_parent_model_frame>1</use_parent_model_frame>
                </axis>
            </joint>

            <link name='l_rear_caster_wheel'>
                <pose frame=''>-0.445 0.37 0.06 0 -0 0</pose>
                <inertial>
                    <pose frame=''>0 0 0 1.5708 -0 0</pose>
                    <mass>2</mass>
                    <inertia>
                        <ixx>0.00206667</ixx>
                        <ixy>0</ixy>
                        <ixz>0</ixz>
                        <iyy>0.00206667</iyy>
                        <iyz>0</iyz>
                        <izz>0.0036</izz>
                    </inertia>
                </inertial>
                <collision name='l_rear_caster_wheel_collision'>
                    <pose frame=''>0 0 0 1.5708 -0 0</pose>
                    <geometry>
                        <cylinder>
                            <length>0.04</length>
                            <radius>0.06</radius>
                        </cylinder>
                    </geometry>
                    <surface>
                        <contact>
                            <ode>
                                <kp>1e+07</kp>
                                <kd>1</kd>
                                <min_depth>0.01</min_depth>
                            </ode>
                        </contact>
                        <friction>
                            <ode>
                                <mu2>1</mu2>
                            </ode>
                        </friction>
                    </surface>
                </collision>
                <visual name='l_rear_caster_wheel_visual'>
                    <pose frame=''>0 0 0 1.5708 -0 0</pose>
                    <geometry>
                        <cylinder>
                            <length>0.04</length>
                            <radius>0.06</radius>
                        </cylinder>
                    </geometry>
                    <material>
                        <ambient>0.1 0.1 0.1 1</ambient>
                        <diffuse>0.1 0.1 0.1 1</diffuse>
                        <specular>0.1 0.1 0.1 1</specular>
                    </material>
                </visual>
                <gravity>1</gravity>
                <velocity_decay/>
            </link>

            <joint name='l_rear_caster_wheel_joint' type='revolute'>
                <child>l_rear_caster_wheel</child>
                <parent>l_rear_caster_rotate</parent>
                <axis>
                    <xyz>0 1 0</xyz>
                    <limit>
                        <lower>-1e+16</lower>
                        <upper>1e+16</upper>
                    </limit>
                    <dynamics>
                        <spring_reference>0</spring_reference>
                        <spring_stiffness>0</spring_stiffness>
                    </dynamics>
                    <use_parent_model_frame>1</use_parent_model_frame>
                </axis>
            </joint>

            <link name='l_wheel'>
                <pose frame=''>0 0.37 0.1 0 -0 0</pose>
                <inertial>
                    <pose frame=''>0 0 0 1.5708 -0 0</pose>
                    <mass>2</mass>
                    <inertia>
                        <ixx>0.2</ixx>
                        <ixy>0</ixy>
                        <ixz>0</ixz>
                        <iyy>0.2</iyy>
                        <iyz>0</iyz>
                        <izz>0.2</izz>
                    </inertia>
                </inertial>
                <collision name='l_wheel_collision'>
                    <pose frame=''>0 0 0 1.5708 -0 0</pose>
                    <geometry>
                        <cylinder>
                            <length>0.06</length>
                            <radius>0.1</radius>
                        </cylinder>
                    </geometry>
                    <surface>
                        <contact>
                            <ode>
                                <kp>1e+07</kp>
                                <kd>1</kd>
                                <min_depth>0.01</min_depth>
                            </ode>
                        </contact>
                        <friction>
                            <ode>
                                <mu2>200</mu2>
                            </ode>
                        </friction>
                    </surface>
                </collision>
                <visual name='l_wheel_visual'>
                    <pose frame=''>0 0 0 1.5708 -0 0</pose>
                    <geometry>
                        <cylinder>
                            <length>0.06</length>
                            <radius>0.1</radius>
                        </cylinder>
                    </geometry>
                    <material>
                        <ambient>0.3 0.3 0.3 1</ambient>
                        <diffuse>0.3 0.3 0.3 1</diffuse>
                        <specular>0.3 0.3 0.3 1</specular>
                    </material>
                </visual>
                <gravity>1</gravity>
                <velocity_decay/>
            </link>
            <joint name='l_wheel_joint' type='revolute'>
                <child>l_wheel</child>
                <parent>l_bogie_suspension</parent>
                <axis>
                    <xyz>0 1 0</xyz>
                    <limit>
                        <lower>-1e+16</lower>
                        <upper>1e+16</upper>
                    </limit>
                    <dynamics>
                        <spring_reference>0</spring_reference>
                        <spring_stiffness>0</spring_stiffness>
                    </dynamics>
                    <use_parent_model_frame>1</use_parent_model_frame>
                </axis>
            </joint>
            <link name='l_front_caster_rotate'>
                <pose frame=''>0.43 0.37 0.15 0 -0 0</pose>
                <inertial>
                    <pose frame=''>0 0 0 0 -0 0</pose>
                    <mass>2</mass>
                    <inertia>
                        <ixx>0.0006</ixx>
                        <ixy>0</ixy>
                        <ixz>0</ixz>
                        <iyy>0.0006</iyy>
                        <iyz>0</iyz>
                        <izz>0.0009</izz>
                    </inertia>
                </inertial>
                <collision name='l_front_caster_rotate_collision'>
                    <pose frame=''>0 0 0 0 -0 0</pose>
                    <geometry>
                        <cylinder>
                            <length>0.03</length>
                            <radius>0.03</radius>
                        </cylinder>
                    </geometry>
                </collision>
                <visual name='l_front_caster_rotate_visual'>
                    <pose frame=''>0 0 0 0 -0 0</pose>
                    <geometry>
                        <cylinder>
                            <length>0.03</length>
                            <radius>0.03</radius>
                        </cylinder>
                    </geometry>
                    <material>
                        <ambient>0.3 0.3 0.3 1</ambient>
                        <diffuse>0.3 0.3 0.3 1</diffuse>
                        <specular>0.3 0.3 0.3 1</specular>
                    </material>
                </visual>
            </link>
            <joint name='l_front_caster_rotate_joint' type='revolute'>
                <child>l_front_caster_rotate</child>
                <parent>base_footprint</parent>
                <axis>
                    <xyz>0 0 1</xyz>
                    <limit>
                        <lower>-1e+16</lower>
                        <upper>1e+16</upper>
                    </limit>
                    <dynamics>
                        <spring_reference>0</spring_reference>
                        <spring_stiffness>0</spring_stiffness>
                    </dynamics>
                    <use_parent_model_frame>1</use_parent_model_frame>
                </axis>
            </joint>
            <link name='l_front_caster_wheel'>
                <pose frame=''>0.415 0.37 0.06 0 -0 0</pose>
                <inertial>
                    <pose frame=''>0 0 0 1.5708 -0 0</pose>
                    <mass>2</mass>
                    <inertia>
                        <ixx>0.00206667</ixx>
                        <ixy>0</ixy>
                        <ixz>0</ixz>
                        <iyy>0.00206667</iyy>
                        <iyz>0</iyz>
                        <izz>0.0036</izz>
                    </inertia>
                </inertial>
                <collision name='l_front_caster_wheel_collision'>
                    <pose frame=''>0 0 0 1.5708 -0 0</pose>
                    <geometry>
                        <cylinder>
                            <length>0.04</length>
                            <radius>0.06</radius>
                        </cylinder>
                    </geometry>
                    <surface>
                        <contact>
                            <ode>
                                <kp>1e+07</kp>
                                <kd>1</kd>
                                <min_depth>0.01</min_depth>
                            </ode>
                        </contact>
                        <friction>
                            <ode>
                                <mu2>1</mu2>
                            </ode>
                        </friction>
                    </surface>
                </collision>
                <visual name='l_front_caster_wheel_visual'>
                    <pose frame=''>0 0 0 1.5708 -0 0</pose>
                    <geometry>
                        <cylinder>
                            <length>0.04</length>
                            <radius>0.06</radius>
                        </cylinder>
                    </geometry>
                    <material>
                        <ambient>0.1 0.1 0.1 1</ambient>
                        <diffuse>0.1 0.1 0.1 1</diffuse>
                        <specular>0.1 0.1 0.1 1</specular>
                    </material>
                </visual>
                <gravity>1</gravity>
                <velocity_decay/>
            </link>
            <joint name='l_front_caster_wheel_joint' type='revolute'>
                <child>l_front_caster_wheel</child>
                <parent>l_front_caster_rotate</parent>
                <axis>
                    <xyz>0 1 0</xyz>
                    <limit>
                        <lower>-1e+16</lower>
                        <upper>1e+16</upper>
                    </limit>
                    <dynamics>
                        <spring_reference>0</spring_reference>
                        <spring_stiffness>0</spring_stiffness>
                    </dynamics>
                    <use_parent_model_frame>1</use_parent_model_frame>
                </axis>
            </joint>
            <link name='r_bogie_suspension'>
                <pose frame=''>-0.25 -0.36 0.15 0 -0 0</pose>
                <inertial>
                    <pose frame=''>0 0.01 0 1.5708 -0 0</pose>
                    <mass>2</mass>
                    <inertia>
                        <ixx>0.00151667</ixx>
                        <ixy>0</ixy>
                        <ixz>0</ixz>
                        <iyy>0.00151667</iyy>
                        <iyz>0</iyz>
                        <izz>0.0009</izz>
                    </inertia>
                </inertial>
                <collision name='r_bogie_suspension_collision'>
                    <pose frame=''>0 0.01 0 1.5708 -0 0</pose>
                    <geometry>
                        <cylinder>
                            <length>0.08</length>
                            <radius>0.03</radius>
                        </cylinder>
                    </geometry>
                </collision>
                <visual name='r_bogie_suspension_visual'>
                    <pose frame=''>0 0.01 0 1.5708 -0 0</pose>
                    <geometry>
                        <cylinder>
                            <length>0.08</length>
                            <radius>0.03</radius>
                        </cylinder>
                    </geometry>
                </visual>
            </link>
            <joint name='r_bogie_suspension_joint' type='revolute'>
                <child>r_bogie_suspension</child>
                <parent>base_footprint</parent>
                <axis>
                    <xyz>0 1 0</xyz>
                    <limit>
                        <lower>-3.14159</lower>
                        <upper>3.14159</upper>
                        <effort>1000</effort>
                        <velocity>0.1</velocity>
                    </limit>
                    <dynamics>
                        <spring_reference>0</spring_reference>
                        <spring_stiffness>0</spring_stiffness>
                    </dynamics>
                    <use_parent_model_frame>1</use_parent_model_frame>
                </axis>
            </joint>
            <link name='r_rear_caster_rotate'>
                <pose frame=''>-0.43 -0.37 0.15 0 -0 0</pose>
                <inertial>
                    <pose frame=''>0 0 0 0 -0 0</pose>
                    <mass>2</mass>
                    <inertia>
                        <ixx>0.0006</ixx>
                        <ixy>0</ixy>
                        <ixz>0</ixz>
                        <iyy>0.0006</iyy>
                        <iyz>0</iyz>
                        <izz>0.0009</izz>
                    </inertia>
                </inertial>
                <collision name='r_rear_caster_rotate_collision'>
                    <pose frame=''>0 0 0 0 -0 0</pose>
                    <geometry>
                        <cylinder>
                            <length>0.03</length>
                            <radius>0.03</radius>
                        </cylinder>
                    </geometry>
                </collision>
                <visual name='r_rear_caster_rotate_visual'>
                    <pose frame=''>0 0 0 0 -0 0</pose>
                    <geometry>
                        <cylinder>
                            <length>0.03</length>
                            <radius>0.03</radius>
                        </cylinder>
                    </geometry>
                </visual>
            </link>
            <joint name='r_rear_caster_rotate_joint' type='revolute'>
                <child>r_rear_caster_rotate</child>
                <parent>r_bogie_suspension</parent>
                <axis>
                    <xyz>0 0 1</xyz>
                    <limit>
                        <lower>-1e+16</lower>
                        <upper>1e+16</upper>
                    </limit>
                    <dynamics>
                        <spring_reference>0</spring_reference>
                        <spring_stiffness>0</spring_stiffness>
                    </dynamics>
                    <use_parent_model_frame>1</use_parent_model_frame>
                </axis>
            </joint>
            <link name='r_rear_caster_wheel'>
                <pose frame=''>-0.445 -0.37 0.06 0 -0 0</pose>
                <inertial>
                    <pose frame=''>0 0 0 1.5708 -0 0</pose>
                    <mass>2</mass>
                    <inertia>
                        <ixx>0.00206667</ixx>
                        <ixy>0</ixy>
                        <ixz>0</ixz>
                        <iyy>0.00206667</iyy>
                        <iyz>0</iyz>
                        <izz>0.0036</izz>
                    </inertia>
                </inertial>
                <collision name='r_rear_caster_wheel_collision'>
                    <pose frame=''>0 0 0 1.5708 -0 0</pose>
                    <geometry>
                        <cylinder>
                            <length>0.04</length>
                            <radius>0.06</radius>
                        </cylinder>
                    </geometry>
                    <surface>
                        <contact>
                            <ode>
                                <kp>1e+07</kp>
                                <kd>1</kd>
                                <min_depth>0.01</min_depth>
                            </ode>
                        </contact>
                        <friction>
                            <ode>
                                <mu2>1</mu2>
                            </ode>
                        </friction>
                    </surface>
                </collision>
                <visual name='r_rear_caster_wheel_visual'>
                    <pose frame=''>0 0 0 1.5708 -0 0</pose>
                    <geometry>
                        <cylinder>
                            <length>0.04</length>
                            <radius>0.06</radius>
                        </cylinder>
                    </geometry>

                </visual>
                <gravity>1</gravity>
                <velocity_decay/>
            </link>
            <joint name='r_rear_caster_wheel_joint' type='revolute'>
                <child>r_rear_caster_wheel</child>
                <parent>r_rear_caster_rotate</parent>
                <axis>
                    <xyz>0 1 0</xyz>
                    <limit>
                        <lower>-1e+16</lower>
                        <upper>1e+16</upper>
                    </limit>
                    <dynamics>
                        <spring_reference>0</spring_reference>
                        <spring_stiffness>0</spring_stiffness>
                    </dynamics>
                    <use_parent_model_frame>1</use_parent_model_frame>
                </axis>
            </joint>
            <link name='r_wheel'>
                <pose frame=''>0 -0.37 0.1 0 -0 0</pose>
                <inertial>
                    <pose frame=''>0 0 0 1.5708 -0 0</pose>
                    <mass>2</mass>
                    <inertia>
                        <ixx>0.2</ixx>
                        <ixy>0</ixy>
                        <ixz>0</ixz>
                        <iyy>0.2</iyy>
                        <iyz>0</iyz>
                        <izz>0.2</izz>
                    </inertia>
                </inertial>
                <collision name='r_wheel_collision'>
                    <pose frame=''>0 0 0 1.5708 -0 0</pose>
                    <geometry>
                        <cylinder>
                            <length>0.06</length>
                            <radius>0.1</radius>
                        </cylinder>
                    </geometry>
                    <surface>
                        <contact>
                            <ode>
                                <kp>1e+07</kp>
                                <kd>1</kd>
                                <min_depth>0.01</min_depth>
                            </ode>
                        </contact>
                        <friction>
                            <ode>
                                <mu2>200</mu2>
                            </ode>
                        </friction>
                    </surface>
                </collision>
                <visual name='r_wheel_visual'>
                    <pose frame=''>0 0 0 1.5708 -0 0</pose>
                    <geometry>
                        <cylinder>
                            <length>0.06</length>
                            <radius>0.1</radius>
                        </cylinder>
                    </geometry>

                </visual>
                <gravity>1</gravity>
                <velocity_decay/>
            </link>
            <joint name='r_wheel_joint' type='revolute'>
                <child>r_wheel</child>
                <parent>r_bogie_suspension</parent>
                <axis>
                    <xyz>0 1 0</xyz>
                    <limit>
                        <lower>-1e+16</lower>
                        <upper>1e+16</upper>
                    </limit>
                    <dynamics>
                        <spring_reference>0</spring_reference>
                        <spring_stiffness>0</spring_stiffness>
                    </dynamics>
                    <use_parent_model_frame>1</use_parent_model_frame>
                </axis>
            </joint>
            <link name='r_front_caster_rotate'>
                <pose frame=''>0.43 -0.37 0.15 0 -0 0</pose>
                <inertial>
                    <pose frame=''>0 0 0 0 -0 0</pose>
                    <mass>2</mass>
                    <inertia>
                        <ixx>0.0006</ixx>
                        <ixy>0</ixy>
                        <ixz>0</ixz>
                        <iyy>0.0006</iyy>
                        <iyz>0</iyz>
                        <izz>0.0009</izz>
                    </inertia>
                </inertial>
                <collision name='r_front_caster_rotate_collision'>
                    <pose frame=''>0 0 0 0 -0 0</pose>
                    <geometry>
                        <cylinder>
                            <length>0.03</length>
                            <radius>0.03</radius>
                        </cylinder>
                    </geometry>
                </collision>
                <visual name='r_front_caster_rotate_visual'>
                    <pose frame=''>0 0 0 0 -0 0</pose>
                    <geometry>
                        <cylinder>
                            <length>0.03</length>
                            <radius>0.03</radius>
                        </cylinder>
                    </geometry>
                </visual>
            </link>
            <joint name='r_front_caster_rotate_joint' type='revolute'>
                <child>r_front_caster_rotate</child>
                <parent>base_footprint</parent>
                <axis>
                    <xyz>0 0 1</xyz>
                    <limit>
                        <lower>-1e+16</lower>
                        <upper>1e+16</upper>
                    </limit>
                    <dynamics>
                        <spring_reference>0</spring_reference>
                        <spring_stiffness>0</spring_stiffness>
                    </dynamics>
                    <use_parent_model_frame>1</use_parent_model_frame>
                </axis>
            </joint>
            <link name='r_front_caster_wheel'>
                <pose frame=''>0.415 -0.37 0.06 0 -0 0</pose>
                <inertial>
                    <pose frame=''>0 0 0 1.5708 -0 0</pose>
                    <mass>2</mass>
                    <inertia>
                        <ixx>0.00206667</ixx>
                        <ixy>0</ixy>
                        <ixz>0</ixz>
                        <iyy>0.00206667</iyy>
                        <iyz>0</iyz>
                        <izz>0.0036</izz>
                    </inertia>
                </inertial>
                <collision name='r_front_caster_wheel_collision'>
                    <pose frame=''>0 0 0 1.5708 -0 0</pose>
                    <geometry>
                        <cylinder>
                            <length>0.04</length>
                            <radius>0.06</radius>
                        </cylinder>
                    </geometry>
                    <surface>
                        <contact>
                            <ode>
                                <kp>1e+07</kp>
                                <kd>1</kd>
                                <min_depth>0.01</min_depth>
                            </ode>
                        </contact>
                        <friction>
                            <ode>
                                <mu2>1</mu2>
                            </ode>
                        </friction>
                    </surface>
                </collision>
                <visual name='r_front_caster_wheel_visual'>
                    <pose frame=''>0 0 0 1.5708 -0 0</pose>
                    <geometry>
                        <cylinder>
                            <length>0.04</length>
                            <radius>0.06</radius>
                        </cylinder>
                    </geometry>

                </visual>
                <gravity>1</gravity>
                <velocity_decay/>
            </link>
            <joint name='r_front_caster_wheel_joint' type='revolute'>
                <child>r_front_caster_wheel</child>
                <parent>r_front_caster_rotate</parent>
                <axis>
                    <xyz>0 1 0</xyz>
                    <limit>
                        <lower>-1e+16</lower>
                        <upper>1e+16</upper>
                    </limit>
                    <dynamics>
                        <spring_reference>0</spring_reference>
                        <spring_stiffness>0</spring_stiffness>
                    </dynamics>
                    <use_parent_model_frame>1</use_parent_model_frame>
                </axis>
            </joint>
            <static>0</static>

            <plugin filename="libignition-gazebo-diff-drive-system.so" name="ignition::gazebo::systems::DiffDrive">
                <left_joint>l_wheel_joint</left_joint>
                <right_joint>r_wheel_joint</right_joint>
                <wheel_separation>0.8</wheel_separation>
                <wheel_radius>0.1</wheel_radius>
            </plugin>
        </model>
    </world>
</sdf>
